Workbook

Sheet Template
A1: Unidade de Negócio | B1: Diretoria / Divisão | C1: Gerência / Área | D1: Matrícula do Colaborador | E1: Nome do Cargo | F1: Grade | G1: Nível Hierárquico | H1: Estado | I1: Cidade | J1: Gênero | K1: Data Contratação | L1: Data Nascimento | M1: Matrícula do Líder | N1: Salário Mensal | O1: Periculosidade + Insalubridade + Outros Adicionais Fixos Mensais | P1: Número de Salários Pagos ao Ano | Q1: Incentivo de Curto Prazo Anual Alvo | R1: Incentivo de Curto Prazo Anual Pago | S1: Incentivo de Longo Prazo Anual Alvo | T1: Incentivo de Longo Prazo Anual Pago | U1: Remuneração Direta Alvo | V1: Camada Organizacional | W1: Span de Controle | X1: Índice de Eficiência Gerencial | Y1: Cargo Líder | Z1: Nível Hierárquico do Líder | AA1: Camada Organizacional do Líder | AB1: Coluna Auxiliar 1 | AC1: Coluna Auxiliar 2 | AE1: company_id
A2: Business_Unit | B2: Group_Macro | C2: Group_Micro | D2: EmployeeID | E2: EmployeeJobTitle | F2: InternalGrade | G2: EmployeeGroup | H2: Estado | I2: Cidade | J2: Gender | K2: HireDate | L2: BirthDate | M2: ManagerEmployeeID | N2: Monthly_Salary | O2: Monthly_FixedAdditives | P2: SalariesPerYear | Q2: ICP_Target | R2: ICP_Paid | S2: ILP_Target | T2: ILP_Paid | U2: RDA | V2: Layer | W2: Span | X2: IEG | Y2: ManagerJobTitle | Z2: ManagerGroup | AA2: ManagerLayer | AB2: AUX_IEG1 | AC2: AUX_IEG2 | AD2: AUX_IEG3 | AE2: ab28b61c-af05-49c5-9d7a-0a76ad62ccfc
A3: MATRIZ | B3: FINANÇAS | C3: TESOURARIA | D3: 20415 | E3: ANALISTA FINANCEIRO PL | F3: 15 | G3: Operacionais / Profissionais | H3: SP | I3: SÃO PAULO | J3: Masculino | K3: 44634 | L3: 27566 | M3: 23251 | N3: 5460 | P3: 13.33 | Q3: 5460 | R3: 0 | U3: =SUM(Template!$N3:$O3)*Template!$P3+Template!$Q3 -> 78241.8 | V3: =IF(Template!$M3="CONSELHO","N",IF(Template!$AA3="N","N1",IF(Template!$AA3="N1","N2",IF(Template!$AA3="N2","N3",IF(Template!$AA3="N3","N4",IF(Template!$AA3="N4","N5",IF(Template!$AA3="N5","N6",IF(Template!$AA3="N6","N7",IF(Template!$AA3="N7","N8",IF(Template!$AA3="N8","N9",IF(Template!$AA3="N9","N10","NA"))))))))))) -> N3 | W3: =COUNTIF(Template!$M$3:$M$619,Template!$D3) -> 0 | X3: =IF(Template!$F3="","",SUMIF(Template!$M$3:$M$619,Template!$D3,Template!$AC$3:$AC$619)) -> 0 | Y3: =IFERROR(VLOOKUP(Template!$M3,Template!$D$3:$G$619,MATCH("EmployeeJobTitle",Template!$D$2:$G$2,0),FALSE),"NA") -> GERENTE DE CONTROLADORIA | Z3: =IFERROR(VLOOKUP(Template!$M3,Template!$D$3:$G$619,MATCH("EmployeeGroup",Template!$D$2:$G$2,0),FALSE),"NA") -> Gerente | AA3: =IFERROR(VLOOKUP(Template!$M3,Template!$D$3:$V$619,MATCH("Layer",Template!$D$2:$V$2,0),FALSE),"NA") -> N2 | AB3: =VLOOKUP(Template!$M3,Template!$D$3:$F$619,MATCH("InternalGrade",Template!$D$2:$F$2,0),FALSE)-Template!$F3 -> 4 | AC3: =IF(Template!$AB3<=1, 0.8,IF(Template!$AB3=2,0.4,IF(Template!$AB3=3,0.2,IF(Template!$AB3=4,0.1,IF(Template!$AB3>=5,0.05,"erro"))))) -> 0.1 | AD3: =Template!$D3=Template!$M3 -> FALSE | AE3: ab28b61c-af05-49c5-9d7a-0a76ad62ccfc
A4: MATRIZ | B4: PRODUTO E ESTILO | C4: GERENCIA DE ESTILO | D4: 16260 | E4: ASSISTENTE ADMINISTRATIVO | F4: 13 | G4: Operacionais / Profissionais | H4: SP | I4: SÃO PAULO | J4: Feminino | K4: 42999 | L4: 31745 | M4: 23265 | N4: 3657.26 | P4: 13.33 | Q4: 3657.26 | R4: 0 | U4: =SUM(Template!$N4:$O4)*Template!$P4+Template!$Q4 -> 52408.536 | V4: =IF(Template!$M4="CONSELHO","N",IF(Template!$AA4="N","N1",IF(Template!$AA4="N1","N2",IF(Template!$AA4="N2","N3",IF(Template!$AA4="N3","N4",IF(Template!$AA4="N4","N5",IF(Template!$AA4="N5","N6",IF(Template!$AA4="N6","N7",IF(Template!$AA4="N7","N8",IF(Template!$AA4="N8","N9",IF(Template!$AA4="N9","N10","NA"))))))))))) -> N2 | W4: =COUNTIF(Template!$M$3:$M$619,Template!$D4) -> 0 | X4: =IF(Template!$F4="","",SUMIF(Template!$M$3:$M$619,Template!$D4,Template!$AC$3:$AC$619)) -> 0 | Y4: =IFERROR(VLOOKUP(Template!$M4,Template!$D$3:$G$619,MATCH("EmployeeJobTitle",Template!$D$2:$G$2,0),FALSE),"NA") -> DIRETORA DE PRODUTO E ESTILO | Z4: =IFERROR(VLOOKUP(Template!$M4,Template!$D$3:$G$619,MATCH("EmployeeGroup",Template!$D$2:$G$2,0),FALSE),"NA") -> Diretor | AA4: =IFERROR(VLOOKUP(Template!$M4,Template!$D$3:$V$619,MATCH("Layer",Template!$D$2:$V$2,0),FALSE),"NA") -> N1 | AB4: =VLOOKUP(Template!$M4,Template!$D$3:$F$619,MATCH("InternalGrade",Template!$D$2:$F$2,0),FALSE)-Template!$F4 -> 8 | AC4: =IF(Template!$AB4<=1, 0.8,IF(Template!$AB4=2,0.4,IF(Template!$AB4=3,0.2,IF(Template!$AB4=4,0.1,IF(Template!$AB4>=5,0.05,"erro"))))) -> 0.05 | AD4: =Template!$D4=Template!$M4 -> FALSE | AE4: ab28b61c-af05-49c5-9d7a-0a76ad62ccfc
A5: MATRIZ | B5: COMPRAS E LOGÍSTICA | C5: GERÊNCIA DE PLANEJAMENTO E ALOCAÇÃO | D5: 17543 | E5: ANALISTA DE PLANEJAMENTO SR | F5: 16 | G5: Operacionais / Profissionais | H5: SP | I5: SÃO PAULO | J5: Feminino | K5: 43507 | L5: 33608 | M5: 18792 | N5: 6123.6 | P5: 13.33 | Q5: 6123.6 | R5: 0 | U5: =SUM(Template!$N5:$O5)*Template!$P5+Template!$Q5 -> 87751.188 | V5: =IF(Template!$M5="CONSELHO","N",IF(Template!$AA5="N","N1",IF(Template!$AA5="N1","N2",IF(Template!$AA5="N2","N3",IF(Template!$AA5="N3","N4",IF(Template!$AA5="N4","N5",IF(Template!$AA5="N5","N6",IF(Template!$AA5="N6","N7",IF(Template!$AA5="N7","N8",IF(Template!$AA5="N8","N9",IF(Template!$AA5="N9","N10","NA"))))))))))) -> N4 | W5: =COUNTIF(Template!$M$3:$M$619,Template!$D5) -> 0 | X5: =IF(Template!$F5="","",SUMIF(Template!$M$3:$M$619,Template!$D5,Template!$AC$3:$AC$619)) -> 0 | Y5: =IFERROR(VLOOKUP(Template!$M5,Template!$D$3:$G$619,MATCH("EmployeeJobTitle",Template!$D$2:$G$2,0),FALSE),"NA") -> COORDENADOR DE PLANEJAMENTO | Z5: =IFERROR(VLOOKUP(Template!$M5,Template!$D$3:$G$619,MATCH("EmployeeGroup",Template!$D$2:$G$2,0),FALSE),"NA") -> Coordenador | AA5: =IFERROR(VLOOKUP(Template!$M5,Template!$D$3:$V$619,MATCH("Layer",Template!$D$2:$V$2,0),FALSE),"NA") -> N3 | AB5: =VLOOKUP(Template!$M5,Template!$D$3:$F$619,MATCH("InternalGrade",Template!$D$2:$F$2,0),FALSE)-Template!$F5 -> 1 | AC5: =IF(Template!$AB5<=1, 0.8,IF(Template!$AB5=2,0.4,IF(Template!$AB5=3,0.2,IF(Template!$AB5=4,0.1,IF(Template!$AB5>=5,0.05,"erro"))))) -> 0.8 | AD5: =Template!$D5=Template!$M5 -> FALSE | AE5: ab28b61c-af05-49c5-9d7a-0a76ad62ccfc
A6: MATRIZ | B6: PRODUTO E ESTILO | C6: GERENCIA DE ESTILO | D6: 20290 | E6: ASSISTENTE DE ESTILO | F6: 13 | G6: Operacionais / Profissionais | H6: SP | I6: SÃO PAULO | J6: Feminino | K6: 44536 | L6: 35751 | M6: 23265 | N6: 3132 | P6: 13.33 | Q6: 3132 | R6: 0 | U6: =SUM(Template!$N6:$O6)*Template!$P6+Template!$Q6 -> 44881.56 | V6: =IF(Template!$M6="CONSELHO","N",IF(Template!$AA6="N","N1",IF(Template!$AA6="N1","N2",IF(Template!$AA6="N2","N3",IF(Template!$AA6="N3","N4",IF(Template!$AA6="N4","N5",IF(Template!$AA6="N5","N6",IF(Template!$AA6="N6","N7",IF(Template!$AA6="N7","N8",IF(Template!$AA6="N8","N9",IF(Template!$AA6="N9","N10","NA"))))))))))) -> N2 | W6: =COUNTIF(Template!$M$3:$M$619,Template!$D6) -> 0 | X6: =IF(Template!$F6="","",SUMIF(Template!$M$3:$M$619,Template!$D6,Template!$AC$3:$AC$619)) -> 0 | Y6: =IFERROR(VLOOKUP(Template!$M6,Template!$D$3:$G$619,MATCH("EmployeeJobTitle",Template!$D$2:$G$2,0),FALSE),"NA") -> DIRETORA DE PRODUTO E ESTILO | Z6: =IFERROR(VLOOKUP(Template!$M6,Template!$D$3:$G$619,MATCH("EmployeeGroup",Template!$D$2:$G$2,0),FALSE),"NA") -> Diretor | AA6: =IFERROR(VLOOKUP(Template!$M6,Template!$D$3:$V$619,MATCH("Layer",Template!$D$2:$V$2,0),FALSE),"NA") -> N1 | AB6: =VLOOKUP(Template!$M6,Template!$D$3:$F$619,MATCH("InternalGrade",Template!$D$2:$F$2,0),FALSE)-Template!$F6 -> 8 | AC6: =IF(Template!$AB6<=1, 0.8,IF(Template!$AB6=2,0.4,IF(Template!$AB6=3,0.2,IF(Template!$AB6=4,0.1,IF(Template!$AB6>=5,0.05,"erro"))))) -> 0.05 | AD6: =Template!$D6=Template!$M6 -> FALSE | AE6: ab28b61c-af05-49c5-9d7a-0a76ad62ccfc
A7: MATRIZ | B7: MARKETING | C7: GERENCIA DE MARKETING | D7: 24279 | E7: DESIGNER PL | F7: 15 | G7: Operacionais / Profissionais | H7: SP | I7: SÃO PAULO | J7: Feminino | K7: 45180 | L7: 36705 | M7: 24771 | N7: 4700 | P7: 13.33 | Q7: 4700 | R7: 0 | U7: =SUM(Template!$N7:$O7)*Template!$P7+Template!$Q7 -> 67351 | V7: =IF(Template!$M7="CONSELHO","N",IF(Template!$AA7="N","N1",IF(Template!$AA7="N1","N2",IF(Template!$AA7="N2","N3",IF(Template!$AA7="N3","N4",IF(Template!$AA7="N4","N5",IF(Template!$AA7="N5","N6",IF(Template!$AA7="N6","N7",IF(Template!$AA7="N7","N8",IF(Template!$AA7="N8","N9",IF(Template!$AA7="N9","N10","NA"))))))))))) -> N4 | W7: =COUNTIF(Template!$M$3:$M$619,Template!$D7) -> 0 | X7: =IF(Template!$F7="","",SUMIF(Template!$M$3:$M$619,Template!$D7,Template!$AC$3:$AC$619)) -> 0 | Y7: =IFERROR(VLOOKUP(Template!$M7,Template!$D$3:$G$619,MATCH("EmployeeJobTitle",Template!$D$2:$G$2,0),FALSE),"NA") -> COORDENADOR DE MARKETING | Z7: =IFERROR(VLOOKUP(Template!$M7,Template!$D$3:$G$619,MATCH("EmployeeGroup",Template!$D$2:$G$2,0),FALSE),"NA") -> Coordenador | AA7: =IFERROR(VLOOKUP(Template!$M7,Template!$D$3:$V$619,MATCH("Layer",Template!$D$2:$V$2,0),FALSE),"NA") -> N3 | AB7: =VLOOKUP(Template!$M7,Template!$D$3:$F$619,MATCH("InternalGrade",Template!$D$2:$F$2,0),FALSE)-Template!$F7 -> 3 | AC7: =IF(Template!$AB7<=1, 0.8,IF(Template!$AB7=2,0.4,IF(Template!$AB7=3,0.2,IF(Template!$AB7=4,0.1,IF(Template!$AB7>=5,0.05,"erro"))))) -> 0.2 | AD7: =Template!$D7=Template!$M7 -> FALSE | AE7: ab28b61c-af05-49c5-9d7a-0a76ad62ccfc
A8: MATRIZ | B8: PRODUTO E ESTILO | C8: GERENCIA DE ESTILO | D8: 24029 | E8: ESTILISTA SR | F8: 18 | G8: Operacionais / Profissionais | H8: SP | I8: SÃO PAULO | J8: Feminino | K8: 45061 | L8: 32492 | M8: 23265 | N8: 18153.33 | P8: 13.33 | Q8: 18153.33 | R8: 0 | U8: =SUM(Template!$N8:$O8)*Template!$P8+Template!$Q8 -> 260137.22 | V8: =IF(Template!$M8="CONSELHO","N",IF(Template!$AA8="N","N1",IF(Template!$AA8="N1","N2",IF(Template!$AA8="N2","N3",IF(Template!$AA8="N3","N4",IF(Template!$AA8="N4","N5",IF(Template!$AA8="N5","N6",IF(Template!$AA8="N6","N7",IF(Template!$AA8="N7","N8",IF(Template!$AA8="N8","N9",IF(Template!$AA8="N9","N10","NA"))))))))))) -> N2 | W8: =COUNTIF(Template!$M$3:$M$619,Template!$D8) -> 0 | X8: =IF(Template!$F8="","",SUMIF(Template!$M$3:$M$619,Template!$D8,Template!$AC$3:$AC$619)) -> 0 | Y8: =IFERROR(VLOOKUP(Template!$M8,Template!$D$3:$G$619,MATCH("EmployeeJobTitle",Template!$D$2:$G$2,0),FALSE),"NA") -> DIRETORA DE PRODUTO E ESTILO | Z8: =IFERROR(VLOOKUP(Template!$M8,Template!$D$3:$G$619,MATCH("EmployeeGroup",Template!$D$2:$G$2,0),FALSE),"NA") -> Diretor | AA8: =IFERROR(VLOOKUP(Template!$M8,Template!$D$3:$V$619,MATCH("Layer",Template!$D$2:$V$2,0),FALSE),"NA") -> N1 | AB8: =VLOOKUP(Template!$M8,Template!$D$3:$F$619,MATCH("InternalGrade",Template!$D$2:$F$2,0),FALSE)-Template!$F8 -> 3 | AC8: =IF(Template!$AB8<=1, 0.8,IF(Template!$AB8=2,0.4,IF(Template!$AB8=3,0.2,IF(Template!$AB8=4,0.1,IF(Template!$AB8>=5,0.05,"erro"))))) -> 0.2 | AD8: =Template!$D8=Template!$M8 -> FALSE | AE8: ab28b61c-af05-49c5-9d7a-0a76ad62ccfc
A9: MATRIZ | B9: FINANÇAS | C9: TESOURARIA | D9: 20506 | E9: ANALISTA FINANCEIRO JR | F9: 14 | G9: Operacionais / Profissionais | H9: SP | I9: SÃO PAULO | J9: Masculino | K9: 44676 | L9: 32125 | M9: 23251 | N9: 4308 | P9: 13.33 | Q9: 4308 | R9: 0 | U9: =SUM(Template!$N9:$O9)*Template!$P9+Template!$Q9 -> 61733.64 | V9: =IF(Template!$M9="CONSELHO","N",IF(Template!$AA9="N","N1",IF(Template!$AA9="N1","N2",IF(Template!$AA9="N2","N3",IF(Template!$AA9="N3","N4",IF(Template!$AA9="N4","N5",IF(Template!$AA9="N5","N6",IF(Template!$AA9="N6","N7",IF(Template!$AA9="N7","N8",IF(Template!$AA9="N8","N9",IF(Template!$AA9="N9","N10","NA"))))))))))) -> N3 | W9: =COUNTIF(Template!$M$3:$M$619,Template!$D9) -> 0 | X9: =IF(Template!$F9="","",SUMIF(Template!$M$3:$M$619,Template!$D9,Template!$AC$3:$AC$619)) -> 0 | Y9: =IFERROR(VLOOKUP(Template!$M9,Template!$D$3:$G$619,MATCH("EmployeeJobTitle",Template!$D$2:$G$2,0),FALSE),"NA") -> GERENTE DE CONTROLADORIA | Z9: =IFERROR(VLOOKUP(Template!$M9,Template!$D$3:$G$619,MATCH("EmployeeGroup",Template!$D$2:$G$2,0),FALSE),"NA") -> Gerente | AA9: =IFERROR(VLOOKUP(Template!$M9,Template!$D$3:$V$619,MATCH("Layer",Template!$D$2:$V$2,0),FALSE),"NA") -> N2 | AB9: =VLOOKUP(Template!$M9,Template!$D$3:$F$619,MATCH("InternalGrade",Template!$D$2:$F$2,0),FALSE)-Template!$F9 -> 5 | AC9: =IF(Template!$AB9<=1, 0.8,IF(Template!$AB9=2,0.4,IF(Template!$AB9=3,0.2,IF(Template!$AB9=4,0.1,IF(Template!$AB9>=5,0.05,"erro"))))) -> 0.05 | AD9: =Template!$D9=Template!$M9 -> FALSE | AE9: ab28b61c-af05-49c5-9d7a-0a76ad62ccfc
A10: MATRIZ | B10: COMERCIAL | C10: GERENCIA DE OPERAÇÕES | D10: 25396 | E10: ANALISTA DE INTELIGENCIA COMERCIAL PL | F10: 15 | G10: Operacionais / Profissionais | H10: SP | I10: SÃO PAULO | J10: Masculino | K10: 45558 | L10: 36033 | M10: 21878 | N10: 5250 | P10: 13.33 | Q10: 5250 | R10: 0 | U10: =SUM(Template!$N10:$O10)*Template!$P10+Template!$Q10 -> 75232.5 | V10: =IF(Template!$M10="CONSELHO","N",IF(Template!$AA10="N","N1",IF(Template!$AA10="N1","N2",IF(Template!$AA10="N2","N3",IF(Template!$AA10="N3","N4",IF(Template!$AA10="N4","N5",IF(Template!$AA10="N5","N6",IF(Template!$AA10="N6","N7",IF(Template!$AA10="N7","N8",IF(Template!$AA10="N8","N9",IF(Template!$AA10="N9","N10","NA"))))))))))) -> N4 | W10: =COUNTIF(Template!$M$3:$M$619,Template!$D10) -> 0 | X10: =IF(Template!$F10="","",SUMIF(Template!$M$3:$M$619,Template!$D10,Template!$AC$3:$AC$619)) -> 0 | Y10: =IFERROR(VLOOKUP(Template!$M10,Template!$D$3:$G$619,MATCH("EmployeeJobTitle",Template!$D$2:$G$2,0),FALSE),"NA") -> COORDENADOR DE INTELIGÊNCIA COMERCIAL | Z10: =IFERROR(VLOOKUP(Template!$M10,Template!$D$3:$G$619,MATCH("EmployeeGroup",Template!$D$2:$G$2,0),FALSE),"NA") -> Coordenador | AA10: =IFERROR(VLOOKUP(Template!$M10,Template!$D$3:$V$619,MATCH("Layer",Template!$D$2:$V$2,0),FALSE),"NA") -> N3 | AB10: =VLOOKUP(Template!$M10,Template!$D$3:$F$619,MATCH("InternalGrade",Template!$D$2:$F$2,0),FALSE)-Template!$F10 -> 3 | AC10: =IF(Template!$AB10<=1, 0.8,IF(Template!$AB10=2,0.4,IF(Template!$AB10=3,0.2,IF(Template!$AB10=4,0.1,IF(Template!$AB10>=5,0.05,"erro"))))) -> 0.2 | AD10: =Template!$D10=Template!$M10 -> FALSE | AE10: ab28b61c-af05-49c5-9d7a-0a76ad62ccfc
A11: MATRIZ | B11: FINANÇAS | C11: TESOURARIA | D11: 11517 | E11: ANALISTA FINANCEIRO SR | F11: 16 | G11: Operacionais / Profissionais | H11: SP | I11: SÃO PAULO | J11: Feminino | K11: 40980 | L11: 30568 | M11: 23251 | N11: 8802 | P11: 13.33 | Q11: 8802 | R11: 0 | U11: =SUM(Template!$N11:$O11)*Template!$P11+Template!$Q11 -> 126132.66 | V11: =IF(Template!$M11="CONSELHO","N",IF(Template!$AA11="N","N1",IF(Template!$AA11="N1","N2",IF(Template!$AA11="N2","N3",IF(Template!$AA11="N3","N4",IF(Template!$AA11="N4","N5",IF(Template!$AA11="N5","N6",IF(Template!$AA11="N6","N7",IF(Template!$AA11="N7","N8",IF(Template!$AA11="N8","N9",IF(Template!$AA11="N9","N10","NA"))))))))))) -> N3 | W11: =COUNTIF(Template!$M$3:$M$619,Template!$D11) -> 0 | X11: =IF(Template!$F11="","",SUMIF(Template!$M$3:$M$619,Template!$D11,Template!$AC$3:$AC$619)) -> 0 | Y11: =IFERROR(VLOOKUP(Template!$M11,Template!$D$3:$G$619,MATCH("EmployeeJobTitle",Template!$D$2:$G$2,0),FALSE),"NA") -> GERENTE DE CONTROLADORIA | Z11: =IFERROR(VLOOKUP(Template!$M11,Template!$D$3:$G$619,MATCH("EmployeeGroup",Template!$D$2:$G$2,0),FALSE),"NA") -> Gerente | AA11: =IFERROR(VLOOKUP(Template!$M11,Template!$D$3:$V$619,MATCH("Layer",Template!$D$2:$V$2,0),FALSE),"NA") -> N2 | AB11: =VLOOKUP(Template!$M11,Template!$D$3:$F$619,MATCH("InternalGrade",Template!$D$2:$F$2,0),FALSE)-Template!$F11 -> 3 | AC11: =IF(Template!$AB11<=1, 0.8,IF(Template!$AB11=2,0.4,IF(Template!$AB11=3,0.2,IF(Template!$AB11=4,0.1,IF(Template!$AB11>=5,0.05,"erro"))))) -> 0.2 | AD11: =Template!$D11=Template!$M11 -> FALSE | AE11: ab28b61c-af05-49c5-9d7a-0a76ad62ccfc
A12: MATRIZ | B12: COMPRAS E LOGÍSTICA | C12: COMPRAS E MANUTENÇÃO | D12: 16889 | E12: AUXILIAR DE SERVIÇOS GERAIS | G12: Operacionais / Profissionais | H12: SP | I12: SÃO PAULO | J12: Feminino | K12: 43264 | L12: 28361 | M12: 18566 | N12: 2021 | P12: 13.33 | Q12: 2021 | R12: 0 | U12: =SUM(Template!$N12:$O12)*Template!$P12+Template!$Q12 -> 28960.93 | V12: =IF(Template!$M12="CONSELHO","N",IF(Template!$AA12="N","N1",IF(Template!$AA12="N1","N2",IF(Template!$AA12="N2","N3",IF(Template!$AA12="N3","N4",IF(Template!$AA12="N4","N5",IF(Template!$AA12="N5","N6",IF(Template!$AA12="N6","N7",IF(Template!$AA12="N7","N8",IF(Template!$AA12="N8","N9",IF(Template!$AA12="N9","N10","NA"))))))))))) -> N3 | W12: =COUNTIF(Template!$M$3:$M$619,Template!$D12) -> 0 | X12: =IF(Template!$F12="","",SUMIF(Template!$M$3:$M$619,Template!$D12,Template!$AC$3:$AC$619)) | Y12: =IFERROR(VLOOKUP(Template!$M12,Template!$D$3:$G$619,MATCH("EmployeeJobTitle",Template!$D$2:$G$2,0),FALSE),"NA") -> COORDENADOR DE COMPRAS | Z12: =IFERROR(VLOOKUP(Template!$M12,Template!$D$3:$G$619,MATCH("EmployeeGroup",Template!$D$2:$G$2,0),FALSE),"NA") -> Coordenador | AA12: =IFERROR(VLOOKUP(Template!$M12,Template!$D$3:$V$619,MATCH("Layer",Template!$D$2:$V$2,0),FALSE),"NA") -> N2 | AB12: =VLOOKUP(Template!$M12,Template!$D$3:$F$619,MATCH("InternalGrade",Template!$D$2:$F$2,0),FALSE)-Template!$F12 -> 18 | AC12: =IF(Template!$AB12<=1, 0.8,IF(Template!$AB12=2,0.4,IF(Template!$AB12=3,0.2,IF(Template!$AB12=4,0.1,IF(Template!$AB12>=5,0.05,"erro"))))) -> 0.05 | AD12: =Template!$D12=Template!$M12 -> FALSE | AE12: ab28b61c-af05-49c5-9d7a-0a76ad62ccfc
A13: MATRIZ | B13: MARKETING | C13: GERENCIA DE MARKETING | D13: 24771 | E13: COORDENADOR DE MARKETING | F13: 18 | G13: Coordenador | H13: SP | I13: SÃO PAULO | J13: Feminino | K13: 45271 | L13: 33392 | M13: 23263 | N13: 13000 | P13: 13.33 | Q13: 19500 | R13: 0 | U13: =SUM(Template!$N13:$O13)*Template!$P13+Template!$Q13 -> 192790 | V13: =IF(Template!$M13="CONSELHO","N",IF(Template!$AA13="N","N1",IF(Template!$AA13="N1","N2",IF(Template!$AA13="N2","N3",IF(Template!$AA13="N3","N4",IF(Template!$AA13="N4","N5",IF(Template!$AA13="N5","N6",IF(Template!$AA13="N6","N7",IF(Template!$AA13="N7","N8",IF(Template!$AA13="N8","N9",IF(Template!$AA13="N9","N10","NA"))))))))))) -> N3 | W13: =COUNTIF(Template!$M$3:$M$619,Template!$D13) -> 6 | X13: =IF(Template!$F13="","",SUMIF(Template!$M$3:$M$619,Template!$D13,Template!$AC$3:$AC$619)) -> 1.25 | Y13: =IFERROR(VLOOKUP(Template!$M13,Template!$D$3:$G$619,MATCH("EmployeeJobTitle",Template!$D$2:$G$2,0),FALSE),"NA") -> GERENTE DE MARKETING | Z13: =IFERROR(VLOOKUP(Template!$M13,Template!$D$3:$G$619,MATCH("EmployeeGroup",Template!$D$2:$G$2,0),FALSE),"NA") -> Gerente | AA13: =IFERROR(VLOOKUP(Template!$M13,Template!$D$3:$V$619,MATCH("Layer",Template!$D$2:$V$2,0),FALSE),"NA") -> N2 | AB13: =VLOOKUP(Template!$M13,Template!$D$3:$F$619,MATCH("InternalGrade",Template!$D$2:$F$2,0),FALSE)-Template!$F13 -> 1 | AC13: =IF(Template!$AB13<=1, 0.8,IF(Template!$AB13=2,0.4,IF(Template!$AB13=3,0.2,IF(Template!$AB13=4,0.1,IF(Template!$AB13>=5,0.05,"erro"))))) -> 0.8 | AD13: =Template!$D13=Template!$M13 -> FALSE | AE13: ab28b61c-af05-49c5-9d7a-0a76ad62ccfc
A14: MATRIZ | B14: COMERCIAL | C14: GERENCIA DE OPERAÇÕES | D14: 21878 | E14: COORDENADOR DE INTELIGÊNCIA COMERCIAL | F14: 18 | G14: Coordenador | H14: SP | I14: SÃO PAULO | J14: Feminino | K14: 44825 | L14: 32316 | M14: 23260 | N14: 12606 | P14: 13.33 | Q14: 18909 | R14: 0 | U14: =SUM(Template!$N14:$O14)*Template!$P14+Template!$Q14 -> 186946.98 | V14: =IF(Template!$M14="CONSELHO","N",IF(Template!$AA14="N","N1",IF(Template!$AA14="N1","N2",IF(Template!$AA14="N2","N3",IF(Template!$AA14="N3","N4",IF(Template!$AA14="N4","N5",IF(Template!$AA14="N5","N6",IF(Template!$AA14="N6","N7",IF(Template!$AA14="N7","N8",IF(Template!$AA14="N8","N9",IF(Template!$AA14="N9","N10","NA"))))))))))) -> N3 | W14: =COUNTIF(Template!$M$3:$M$619,Template!$D14) -> 2 | X14: =IF(Template!$F14="","",SUMIF(Template!$M$3:$M$619,Template!$D14,Template!$AC$3:$AC$619)) -> 0.4 | Y14: =IFERROR(VLOOKUP(Template!$M14,Template!$D$3:$G$619,MATCH("EmployeeJobTitle",Template!$D$2:$G$2,0),FALSE),"NA") -> GERENTE PLANEJAMENTO ESTRATEGICO | Z14: =IFERROR(VLOOKUP(Template!$M14,Template!$D$3:$G$619,MATCH("EmployeeGroup",Template!$D$2:$G$2,0),FALSE),"NA") -> Gerente | AA14: =IFERROR(VLOOKUP(Template!$M14,Template!$D$3:$V$619,MATCH("Layer",Template!$D$2:$V$2,0),FALSE),"NA") -> N2 | AB14: =VLOOKUP(Template!$M14,Template!$D$3:$F$619,MATCH("InternalGrade",Template!$D$2:$F$2,0),FALSE)-Template!$F14 -> 0 | AC14: =IF(Template!$AB14<=1, 0.8,IF(Template!$AB14=2,0.4,IF(Template!$AB14=3,0.2,IF(Template!$AB14=4,0.1,IF(Template!$AB14>=5,0.05,"erro"))))) -> 0.8 | AD14: =Template!$D14=Template!$M14 -> FALSE | AE14: ab28b61c-af05-49c5-9d7a-0a76ad62ccfc
A15: MATRIZ | B15: MARKETING | C15: GERENCIA DE VISUAL MERCHADISING | D15: 24390 | E15: CONSULTOR DE VISUAL MERCHANDISING | F15: 14 | G15: Operacionais / Profissionais | H15: SP | I15: SÃO PAULO | J15: Feminino | K15: 45222 | L15: 30265 | M15: 23266 | N15: 5000 | P15: 13.33 | Q15: 5000 | R15: 0 | U15: =SUM(Template!$N15:$O15)*Template!$P15+Template!$Q15 -> 71650 | V15: =IF(Template!$M15="CONSELHO","N",IF(Template!$AA15="N","N1",IF(Template!$AA15="N1","N2",IF(Template!$AA15="N2","N3",IF(Template!$AA15="N3","N4",IF(Template!$AA15="N4","N5",IF(Template!$AA15="N5","N6",IF(Template!$AA15="N6","N7",IF(Template!$AA15="N7","N8",IF(Template!$AA15="N8","N9",IF(Template!$AA15="N9","N10","NA"))))))))))) -> N3 | W15: =COUNTIF(Template!$M$3:$M$619,Template!$D15) -> 0 | X15: =IF(Template!$F15="","",SUMIF(Template!$M$3:$M$619,Template!$D15,Template!$AC$3:$AC$619)) -> 0 | Y15: =IFERROR(VLOOKUP(Template!$M15,Template!$D$3:$G$619,MATCH("EmployeeJobTitle",Template!$D$2:$G$2,0),FALSE),"NA") -> GERENTE DE VM | Z15: =IFERROR(VLOOKUP(Template!$M15,Template!$D$3:$G$619,MATCH("EmployeeGroup",Template!$D$2:$G$2,0),FALSE),"NA") -> Gerente | AA15: =IFERROR(VLOOKUP(Template!$M15,Template!$D$3:$V$619,MATCH("Layer",Template!$D$2:$V$2,0),FALSE),"NA") -> N2 | AB15: =VLOOKUP(Template!$M15,Template!$D$3:$F$619,MATCH("InternalGrade",Template!$D$2:$F$2,0),FALSE)-Template!$F15 -> 5 | AC15: =IF(Template!$AB15<=1, 0.8,IF(Template!$AB15=2,0.4,IF(Template!$AB15=3,0.2,IF(Template!$AB15=4,0.1,IF(Template!$AB15>=5,0.05,"erro"))))) -> 0.05 | AD15: =Template!$D15=Template!$M15 -> FALSE | AE15: ab28b61c-af05-49c5-9d7a-0a76ad62ccfc
A16: MATRIZ | B16: TECNOLOGIA DA INFORMAÇÃO | C16: TECNOLOGIA DA INFORMAÇÃO | D16: 24838 | E16: ANALISTA DE TI PL | F16: 15 | G16: Operacionais / Profissionais | H16: SP | I16: SÃO PAULO | J16: Masculino | K16: 45323 | L16: 35061 | M16: 25348 | N16: 4532 | P16: 13.33 | Q16: 4532 | R16: 0 | U16: =SUM(Template!$N16:$O16)*Template!$P16+Template!$Q16 -> 64943.56 | V16: =IF(Template!$M16="CONSELHO","N",IF(Template!$AA16="N","N1",IF(Template!$AA16="N1","N2",IF(Template!$AA16="N2","N3",IF(Template!$AA16="N3","N4",IF(Template!$AA16="N4","N5",IF(Template!$AA16="N5","N6",IF(Template!$AA16="N6","N7",IF(Template!$AA16="N7","N8",IF(Template!$AA16="N8","N9",IF(Template!$AA16="N9","N10","NA"))))))))))) -> N3 | W16: =COUNTIF(Template!$M$3:$M$619,Template!$D16) -> 0 | X16: =IF(Template!$F16="","",SUMIF(Template!$M$3:$M$619,Template!$D16,Template!$AC$3:$AC$619)) -> 0 | Y16: =IFERROR(VLOOKUP(Template!$M16,Template!$D$3:$G$619,MATCH("EmployeeJobTitle",Template!$D$2:$G$2,0),FALSE),"NA") -> COORDENADOR DE TI | Z16: =IFERROR(VLOOKUP(Template!$M16,Template!$D$3:$G$619,MATCH("EmployeeGroup",Template!$D$2:$G$2,0),FALSE),"NA") -> Coordenador | AA16: =IFERROR(VLOOKUP(Template!$M16,Template!$D$3:$V$619,MATCH("Layer",Template!$D$2:$V$2,0),FALSE),"NA") -> N2 | AB16: =VLOOKUP(Template!$M16,Template!$D$3:$F$619,MATCH("InternalGrade",Template!$D$2:$F$2,0),FALSE)-Template!$F16 -> 3 | AC16: =IF(Template!$AB16<=1, 0.8,IF(Template!$AB16=2,0.4,IF(Template!$AB16=3,0.2,IF(Template!$AB16=4,0.1,IF(Template!$AB16>=5,0.05,"erro"))))) -> 0.2 | AD16: =Template!$D16=Template!$M16 -> FALSE | AE16: ab28b61c-af05-49c5-9d7a-0a76ad62ccfc
A17: MATRIZ | B17: COMPRAS E LOGÍSTICA | C17: GERÊNCIA DE PLANEJAMENTO E ALOCAÇÃO | D17: 18792 | E17: COORDENADOR DE PLANEJAMENTO | F17: 17 | G17: Coordenador | H17: SP | I17: SÃO PAULO | J17: Feminino | K17: 44123 | L17: 33722 | M17: 14021 | N17: 11105.53 | P17: 13.33 | Q17: 16658.295 | R17: 0 | U17: =SUM(Template!$N17:$O17)*Template!$P17+Template!$Q17 -> 164695.01 | V17: =IF(Template!$M17="CONSELHO","N",IF(Template!$AA17="N","N1",IF(Template!$AA17="N1","N2",IF(Template!$AA17="N2","N3",IF(Template!$AA17="N3","N4",IF(Template!$AA17="N4","N5",IF(Template!$AA17="N5","N6",IF(Template!$AA17="N6","N7",IF(Template!$AA17="N7","N8",IF(Template!$AA17="N8","N9",IF(Template!$AA17="N9","N10","NA"))))))))))) -> N3 | W17: =COUNTIF(Template!$M$3:$M$619,Template!$D17) -> 5 | X17: =IF(Template!$F17="","",SUMIF(Template!$M$3:$M$619,Template!$D17,Template!$AC$3:$AC$619)) -> 1.8 | Y17: =IFERROR(VLOOKUP(Template!$M17,Template!$D$3:$G$619,MATCH("EmployeeJobTitle",Template!$D$2:$G$2,0),FALSE),"NA") -> GERENTE DE PLANEJAMENTO | Z17: =IFERROR(VLOOKUP(Template!$M17,Template!$D$3:$G$619,MATCH("EmployeeGroup",Template!$D$2:$G$2,0),FALSE),"NA") -> Gerente | AA17: =IFERROR(VLOOKUP(Template!$M17,Template!$D$3:$V$619,MATCH("Layer",Template!$D$2:$V$2,0),FALSE),"NA") -> N2 | AB17: =VLOOKUP(Template!$M17,Template!$D$3:$F$619,MATCH("InternalGrade",Template!$D$2:$F$2,0),FALSE)-Template!$F17 -> 2 | AC17: =IF(Template!$AB17<=1, 0.8,IF(Template!$AB17=2,0.4,IF(Template!$AB17=3,0.2,IF(Template!$AB17=4,0.1,IF(Template!$AB17>=5,0.05,"erro"))))) -> 0.4 | AD17: =Template!$D17=Template!$M17 -> FALSE | AE17: ab28b61c-af05-49c5-9d7a-0a76ad62ccfc
A18: MATRIZ | B18: COMERCIAL | C18: E-COMMERCE | D18: 19402 | E18: ASSISTENTE DE VENDAS E-COMMERCE | F18: 12 | G18: Operacionais / Profissionais | H18: SP | I18: SÃO PAULO | J18: Feminino | K18: 44245 | L18: 33607 | M18: 20450 | N18: 2455 | P18: 13.33 | Q18: 2455 | R18: 0 | U18: =SUM(Template!$N18:$O18)*Template!$P18+Template!$Q18 -> 35180.15 | V18: =IF(Template!$M18="CONSELHO","N",IF(Template!$AA18="N","N1",IF(Template!$AA18="N1","N2",IF(Template!$AA18="N2","N3",IF(Template!$AA18="N3","N4",IF(Template!$AA18="N4","N5",IF(Template!$AA18="N5","N6",IF(Template!$AA18="N6","N7",IF(Template!$AA18="N7","N8",IF(Template!$AA18="N8","N9",IF(Template!$AA18="N9","N10","NA"))))))))))) -> N3 | W18: =COUNTIF(Template!$M$3:$M$619,Template!$D18) -> 0 | X18: =IF(Template!$F18="","",SUMIF(Template!$M$3:$M$619,Template!$D18,Template!$AC$3:$AC$619)) -> 0 | Y18: =IFERROR(VLOOKUP(Template!$M18,Template!$D$3:$G$619,MATCH("EmployeeJobTitle",Template!$D$2:$G$2,0),FALSE),"NA") -> COORDENADOR DE ECOMMERCE | Z18: =IFERROR(VLOOKUP(Template!$M18,Template!$D$3:$G$619,MATCH("EmployeeGroup",Template!$D$2:$G$2,0),FALSE),"NA") -> Coordenador | AA18: =IFERROR(VLOOKUP(Template!$M18,Template!$D$3:$V$619,MATCH("Layer",Template!$D$2:$V$2,0),FALSE),"NA") -> N2 | AB18: =VLOOKUP(Template!$M18,Template!$D$3:$F$619,MATCH("InternalGrade",Template!$D$2:$F$2,0),FALSE)-Template!$F18 -> 6 | AC18: =IF(Template!$AB18<=1, 0.8,IF(Template!$AB18=2,0.4,IF(Template!$AB18=3,0.2,IF(Template!$AB18=4,0.1,IF(Template!$AB18>=5,0.05,"erro"))))) -> 0.05 | AD18: =Template!$D18=Template!$M18 -> FALSE | AE18: ab28b61c-af05-49c5-9d7a-0a76ad62ccfc
A19: MATRIZ | B19: RECURSOS HUMANOS | C19: DEPARTAMENTO PESSOAL | D19: 20505 | E19: COORDENADOR DE RECURSOS HUMANOS | F19: 18 | G19: Coordenador | H19: SP | I19: SÃO PAULO | J19: Masculino | K19: 44676 | L19: 29995 | M19: 23262 | N19: 14085 | P19: 13.33 | Q19: 21127.5 | R19: 0 | U19: =SUM(Template!$N19:$O19)*Template!$P19+Template!$Q19 -> 208880.55 | V19: =IF(Template!$M19="CONSELHO","N",IF(Template!$AA19="N","N1",IF(Template!$AA19="N1","N2",IF(Template!$AA19="N2","N3",IF(Template!$AA19="N3","N4",IF(Template!$AA19="N4","N5",IF(Template!$AA19="N5","N6",IF(Template!$AA19="N6","N7",IF(Template!$AA19="N7","N8",IF(Template!$AA19="N8","N9",IF(Template!$AA19="N9","N10","NA"))))))))))) -> N2 | W19: =COUNTIF(Template!$M$3:$M$619,Template!$D19) -> 1 | X19: =IF(Template!$F19="","",SUMIF(Template!$M$3:$M$619,Template!$D19,Template!$AC$3:$AC$619)) -> 0.05 | Y19: =IFERROR(VLOOKUP(Template!$M19,Template!$D$3:$G$619,MATCH("EmployeeJobTitle",Template!$D$2:$G$2,0),FALSE),"NA") -> DIRETORA DE RECURSOS HUMANOS | Z19: =IFERROR(VLOOKUP(Template!$M19,Template!$D$3:$G$619,MATCH("EmployeeGroup",Template!$D$2:$G$2,0),FALSE),"NA") -> Diretor | AA19: =IFERROR(VLOOKUP(Template!$M19,Template!$D$3:$V$619,MATCH("Layer",Template!$D$2:$V$2,0),FALSE),"NA") -> N1 | AB19: =VLOOKUP(Template!$M19,Template!$D$3:$F$619,MATCH("InternalGrade",Template!$D$2:$F$2,0),FALSE)-Template!$F19 -> 3 | AC19: =IF(Template!$AB19<=1, 0.8,IF(Template!$AB19=2,0.4,IF(Template!$AB19=3,0.2,IF(Template!$AB19=4,0.1,IF(Template!$AB19>=5,0.05,"erro"))))) -> 0.2 | AD19: =Template!$D19=Template!$M19 -> FALSE | AE19: ab28b61c-af05-49c5-9d7a-0a76ad62ccfc
A20: MATRIZ | B20: FINANÇAS | C20: CONTROLADORIA | D20: 11398 | E20: COORDENADOR FISCAL | F20: 18 | G20: Coordenador | H20: SP | I20: SÃO PAULO | J20: Masculino | K20: 40931 | L20: 27620 | M20: 23251 | N20: 13444 | P20: 13.33 | Q20: 20166 | R20: 0 | U20: =SUM(Template!$N20:$O20)*Template!$P20+Template!$Q20 -> 199374.52 | V20: =IF(Template!$M20="CONSELHO","N",IF(Template!$AA20="N","N1",IF(Template!$AA20="N1","N2",IF(Template!$AA20="N2","N3",IF(Template!$AA20="N3","N4",IF(Template!$AA20="N4","N5",IF(Template!$AA20="N5","N6",IF(Template!$AA20="N6","N7",IF(Template!$AA20="N7","N8",IF(Template!$AA20="N8","N9",IF(Template!$AA20="N9","N10","NA"))))))))))) -> N3 | W20: =COUNTIF(Template!$M$3:$M$619,Template!$D20) -> 4 | X20: =IF(Template!$F20="","",SUMIF(Template!$M$3:$M$619,Template!$D20,Template!$AC$3:$AC$619)) -> 1.05 | Y20: =IFERROR(VLOOKUP(Template!$M20,Template!$D$3:$G$619,MATCH("EmployeeJobTitle",Template!$D$2:$G$2,0),FALSE),"NA") -> GERENTE DE CONTROLADORIA | Z20: =IFERROR(VLOOKUP(Template!$M20,Template!$D$3:$G$619,MATCH("EmployeeGroup",Template!$D$2:$G$2,0),FALSE),"NA") -> Gerente | AA20: =IFERROR(VLOOKUP(Template!$M20,Template!$D$3:$V$619,MATCH("Layer",Template!$D$2:$V$2,0),FALSE),"NA") -> N2 | AB20: =VLOOKUP(Template!$M20,Template!$D$3:$F$619,MATCH("InternalGrade",Template!$D$2:$F$2,0),FALSE)-Template!$F20 -> 1 | AC20: =IF(Template!$AB20<=1, 0.8,IF(Template!$AB20=2,0.4,IF(Template!$AB20=3,0.2,IF(Template!$AB20=4,0.1,IF(Template!$AB20>=5,0.05,"erro"))))) -> 0.8 | AD20: =Template!$D20=Template!$M20 -> FALSE | AE20: ab28b61c-af05-49c5-9d7a-0a76ad62ccfc
A21: MATRIZ | B21: FINANÇAS | C21: TESOURARIA | D21: 13338 | E21: ANALISTA FINANCEIRO JR | F21: 14 | G21: Operacionais / Profissionais | H21: SP | I21: SÃO PAULO | J21: Feminino | K21: 41730 | L21: 35335 | M21: 23251 | N21: 4146 | P21: 13.33 | Q21: 4146 | R21: 0 | U21: =SUM(Template!$N21:$O21)*Template!$P21+Template!$Q21 -> 59412.18 | V21: =IF(Template!$M21="CONSELHO","N",IF(Template!$AA21="N","N1",IF(Template!$AA21="N1","N2",IF(Template!$AA21="N2","N3",IF(Template!$AA21="N3","N4",IF(Template!$AA21="N4","N5",IF(Template!$AA21="N5","N6",IF(Template!$AA21="N6","N7",IF(Template!$AA21="N7","N8",IF(Template!$AA21="N8","N9",IF(Template!$AA21="N9","N10","NA"))))))))))) -> N3 | W21: =COUNTIF(Template!$M$3:$M$619,Template!$D21) -> 0 | X21: =IF(Template!$F21="","",SUMIF(Template!$M$3:$M$619,Template!$D21,Template!$AC$3:$AC$619)) -> 0 | Y21: =IFERROR(VLOOKUP(Template!$M21,Template!$D$3:$G$619,MATCH("EmployeeJobTitle",Template!$D$2:$G$2,0),FALSE),"NA") -> GERENTE DE CONTROLADORIA | Z21: =IFERROR(VLOOKUP(Template!$M21,Template!$D$3:$G$619,MATCH("EmployeeGroup",Template!$D$2:$G$2,0),FALSE),"NA") -> Gerente | AA21: =IFERROR(VLOOKUP(Template!$M21,Template!$D$3:$V$619,MATCH("Layer",Template!$D$2:$V$2,0),FALSE),"NA") -> N2 | AB21: =VLOOKUP(Template!$M21,Template!$D$3:$F$619,MATCH("InternalGrade",Template!$D$2:$F$2,0),FALSE)-Template!$F21 -> 5 | AC21: =IF(Template!$AB21<=1, 0.8,IF(Template!$AB21=2,0.4,IF(Template!$AB21=3,0.2,IF(Template!$AB21=4,0.1,IF(Template!$AB21>=5,0.05,"erro"))))) -> 0.05 | AD21: =Template!$D21=Template!$M21 -> FALSE | AE21: ab28b61c-af05-49c5-9d7a-0a76ad62ccfc
A22: MATRIZ | B22: FINANÇAS | C22: JURIDICO | D22: 25223 | E22: ASSISTENTE JURIDICO | F22: 13 | G22: Operacionais / Profissionais | H22: SP | I22: SÃO PAULO | J22: Feminino | K22: 45495 | L22: 37426 | M22: 14066 | N22: 2800 | P22: 13.33 | Q22: 2800 | R22: 0 | U22: =SUM(Template!$N22:$O22)*Template!$P22+Template!$Q22 -> 40124 | V22: =IF(Template!$M22="CONSELHO","N",IF(Template!$AA22="N","N1",IF(Template!$AA22="N1","N2",IF(Template!$AA22="N2","N3",IF(Template!$AA22="N3","N4",IF(Template!$AA22="N4","N5",IF(Template!$AA22="N5","N6",IF(Template!$AA22="N6","N7",IF(Template!$AA22="N7","N8",IF(Template!$AA22="N8","N9",IF(Template!$AA22="N9","N10","NA"))))))))))) -> N3 | W22: =COUNTIF(Template!$M$3:$M$619,Template!$D22) -> 0 | X22: =IF(Template!$F22="","",SUMIF(Template!$M$3:$M$619,Template!$D22,Template!$AC$3:$AC$619)) -> 0 | Y22: =IFERROR(VLOOKUP(Template!$M22,Template!$D$3:$G$619,MATCH("EmployeeJobTitle",Template!$D$2:$G$2,0),FALSE),"NA") -> GERENTE JURIDICO | Z22: =IFERROR(VLOOKUP(Template!$M22,Template!$D$3:$G$619,MATCH("EmployeeGroup",Template!$D$2:$G$2,0),FALSE),"NA") -> Gerente | AA22: =IFERROR(VLOOKUP(Template!$M22,Template!$D$3:$V$619,MATCH("Layer",Template!$D$2:$V$2,0),FALSE),"NA") -> N2 | AB22: =VLOOKUP(Template!$M22,Template!$D$3:$F$619,MATCH("InternalGrade",Template!$D$2:$F$2,0),FALSE)-Template!$F22 -> 6 | AC22: =IF(Template!$AB22<=1, 0.8,IF(Template!$AB22=2,0.4,IF(Template!$AB22=3,0.2,IF(Template!$AB22=4,0.1,IF(Template!$AB22>=5,0.05,"erro"))))) -> 0.05 | AD22: =Template!$D22=Template!$M22 -> FALSE | AE22: ab28b61c-af05-49c5-9d7a-0a76ad62ccfc
A23: MATRIZ | B23: COMERCIAL | C23: ARQUITETURA | D23: 24235 | E23: ANALISTA DE GESTÃO DE PROJETOS JR | F23: 14 | G23: Operacionais / Profissionais | H23: SP | I23: SÃO PAULO | J23: Feminino | K23: 45159 | L23: 34668 | M23: 25195 | N23: 3179 | P23: 13.33 | Q23: 3179 | R23: 0 | U23: =SUM(Template!$N23:$O23)*Template!$P23+Template!$Q23 -> 45555.07 | V23: =IF(Template!$M23="CONSELHO","N",IF(Template!$AA23="N","N1",IF(Template!$AA23="N1","N2",IF(Template!$AA23="N2","N3",IF(Template!$AA23="N3","N4",IF(Template!$AA23="N4","N5",IF(Template!$AA23="N5","N6",IF(Template!$AA23="N6","N7",IF(Template!$AA23="N7","N8",IF(Template!$AA23="N8","N9",IF(Template!$AA23="N9","N10","NA"))))))))))) -> N3 | W23: =COUNTIF(Template!$M$3:$M$619,Template!$D23) -> 0 | X23: =IF(Template!$F23="","",SUMIF(Template!$M$3:$M$619,Template!$D23,Template!$AC$3:$AC$619)) -> 0 | Y23: =IFERROR(VLOOKUP(Template!$M23,Template!$D$3:$G$619,MATCH("EmployeeJobTitle",Template!$D$2:$G$2,0),FALSE),"NA") -> GERENTE DE EXPANSÃO, IMPLANTAÇÃO E PROJETOS | Z23: =IFERROR(VLOOKUP(Template!$M23,Template!$D$3:$G$619,MATCH("EmployeeGroup",Template!$D$2:$G$2,0),FALSE),"NA") -> Gerente | AA23: =IFERROR(VLOOKUP(Template!$M23,Template!$D$3:$V$619,MATCH("Layer",Template!$D$2:$V$2,0),FALSE),"NA") -> N2 | AB23: =VLOOKUP(Template!$M23,Template!$D$3:$F$619,MATCH("InternalGrade",Template!$D$2:$F$2,0),FALSE)-Template!$F23 -> 6 | AC23: =IF(Template!$AB23<=1, 0.8,IF(Template!$AB23=2,0.4,IF(Template!$AB23=3,0.2,IF(Template!$AB23=4,0.1,IF(Template!$AB23>=5,0.05,"erro"))))) -> 0.05 | AD23: =Template!$D23=Template!$M23 -> FALSE | AE23: ab28b61c-af05-49c5-9d7a-0a76ad62ccfc
A24: MATRIZ | B24: FINANÇAS | C24: JURIDICO | D24: 25379 | E24: ADVOGADO JR | F24: 15 | G24: Operacionais / Profissionais | H24: SP | I24: SÃO PAULO | J24: Masculino | K24: 45551 | L24: 36327 | M24: 14066 | N24: 5200 | P24: 13.33 | Q24: 5200 | R24: 0 | U24: =SUM(Template!$N24:$O24)*Template!$P24+Template!$Q24 -> 74516 | V24: =IF(Template!$M24="CONSELHO","N",IF(Template!$AA24="N","N1",IF(Template!$AA24="N1","N2",IF(Template!$AA24="N2","N3",IF(Template!$AA24="N3","N4",IF(Template!$AA24="N4","N5",IF(Template!$AA24="N5","N6",IF(Template!$AA24="N6","N7",IF(Template!$AA24="N7","N8",IF(Template!$AA24="N8","N9",IF(Template!$AA24="N9","N10","NA"))))))))))) -> N3 | W24: =COUNTIF(Template!$M$3:$M$619,Template!$D24) -> 0 | X24: =IF(Template!$F24="","",SUMIF(Template!$M$3:$M$619,Template!$D24,Template!$AC$3:$AC$619)) -> 0 | Y24: =IFERROR(VLOOKUP(Template!$M24,Template!$D$3:$G$619,MATCH("EmployeeJobTitle",Template!$D$2:$G$2,0),FALSE),"NA") -> GERENTE JURIDICO | Z24: =IFERROR(VLOOKUP(Template!$M24,Template!$D$3:$G$619,MATCH("EmployeeGroup",Template!$D$2:$G$2,0),FALSE),"NA") -> Gerente | AA24: =IFERROR(VLOOKUP(Template!$M24,Template!$D$3:$V$619,MATCH("Layer",Template!$D$2:$V$2,0),FALSE),"NA") -> N2 | AB24: =VLOOKUP(Template!$M24,Template!$D$3:$F$619,MATCH("InternalGrade",Template!$D$2:$F$2,0),FALSE)-Template!$F24 -> 4 | AC24: =IF(Template!$AB24<=1, 0.8,IF(Template!$AB24=2,0.4,IF(Template!$AB24=3,0.2,IF(Template!$AB24=4,0.1,IF(Template!$AB24>=5,0.05,"erro"))))) -> 0.1 | AD24: =Template!$D24=Template!$M24 -> FALSE | AE24: ab28b61c-af05-49c5-9d7a-0a76ad62ccfc
... A59: MATRIZ | B59: TECNOLOGIA DA INFORMAÇÃO | C59: TECNOLOGIA DA INFORMAÇÃO | D59: 25208 | E59: ANALISTA DE TI JR | F59: 14 | G59: Operacionais / Profissionais | H59: SP | I59: SÃO PAULO | J59: Feminino | K59: 45488 | L59: 37966 | M59: 25348 | N59: 3464 | P59: 13.33 | Q59: 3464 | R59: 0 | U59: =SUM(Template!$N59:$O59)*Template!$P59+Template!$Q59 -> 49639.12 | V59: =IF(Template!$M59="CONSELHO","N",IF(Template!$AA59="N","N1",IF(Template!$AA59="N1","N2",IF(Template!$AA59="N2","N3",IF(Template!$AA59="N3","N4",IF(Template!$AA59="N4","N5",IF(Template!$AA59="N5","N6",IF(Template!$AA59="N6","N7",IF(Template!$AA59="N7","N8",IF(Template!$AA59="N8","N9",IF(Template!$AA59="N9","N10","NA"))))))))))) -> N3 | W59: =COUNTIF(Template!$M$3:$M$619,Template!$D59) -> 0 | X59: =IF(Template!$F59="","",SUMIF(Template!$M$3:$M$619,Template!$D59,Template!$AC$3:$AC$619)) -> 0 | Y59: =IFERROR(VLOOKUP(Template!$M59,Template!$D$3:$G$619,MATCH("EmployeeJobTitle",Template!$D$2:$G$2,0),FALSE),"NA") -> COORDENADOR DE TI | Z59: =IFERROR(VLOOKUP(Template!$M59,Template!$D$3:$G$619,MATCH("EmployeeGroup",Template!$D$2:$G$2,0),FALSE),"NA") -> Coordenador | AA59: =IFERROR(VLOOKUP(Template!$M59,Template!$D$3:$V$619,MATCH("Layer",Template!$D$2:$V$2,0),FALSE),"NA") -> N2 | AB59: =VLOOKUP(Template!$M59,Template!$D$3:$F$619,MATCH("InternalGrade",Template!$D$2:$F$2,0),FALSE)-Template!$F59 -> 4 | AC59: =IF(Template!$AB59<=1, 0.8,IF(Template!$AB59=2,0.4,IF(Template!$AB59=3,0.2,IF(Template!$AB59=4,0.1,IF(Template!$AB59>=5,0.05,"erro"))))) -> 0.1 | AD59: =Template!$D59=Template!$M59 -> FALSE | AE59: ab28b61c-af05-49c5-9d7a-0a76ad62ccfc
A60: MATRIZ | B60: COMPRAS E LOGÍSTICA | C60: COMPRAS E MANUTENÇÃO | D60: 14514 | E60: ENCARREGADO DE MANUTENÇÃO | G60: Coordenador | H60: SP | I60: SÃO PAULO | J60: Masculino | K60: 42282 | L60: 22778 | M60: 18566 | N60: 5001.26 | P60: 13.33 | Q60: 5001.26 | R60: 0 | U60: =SUM(Template!$N60:$O60)*Template!$P60+Template!$Q60 -> 71668.056 | V60: =IF(Template!$M60="CONSELHO","N",IF(Template!$AA60="N","N1",IF(Template!$AA60="N1","N2",IF(Template!$AA60="N2","N3",IF(Template!$AA60="N3","N4",IF(Template!$AA60="N4","N5",IF(Template!$AA60="N5","N6",IF(Template!$AA60="N6","N7",IF(Template!$AA60="N7","N8",IF(Template!$AA60="N8","N9",IF(Template!$AA60="N9","N10","NA"))))))))))) -> N3 | W60: =COUNTIF(Template!$M$3:$M$619,Template!$D60) -> 0 | X60: =IF(Template!$F60="","",SUMIF(Template!$M$3:$M$619,Template!$D60,Template!$AC$3:$AC$619)) | Y60: =IFERROR(VLOOKUP(Template!$M60,Template!$D$3:$G$619,MATCH("EmployeeJobTitle",Template!$D$2:$G$2,0),FALSE),"NA") -> COORDENADOR DE COMPRAS | Z60: =IFERROR(VLOOKUP(Template!$M60,Template!$D$3:$G$619,MATCH("EmployeeGroup",Template!$D$2:$G$2,0),FALSE),"NA") -> Coordenador | AA60: =IFERROR(VLOOKUP(Template!$M60,Template!$D$3:$V$619,MATCH("Layer",Template!$D$2:$V$2,0),FALSE),"NA") -> N2 | AB60: =VLOOKUP(Template!$M60,Template!$D$3:$F$619,MATCH("InternalGrade",Template!$D$2:$F$2,0),FALSE)-Template!$F60 -> 18 | AC60: =IF(Template!$AB60<=1, 0.8,IF(Template!$AB60=2,0.4,IF(Template!$AB60=3,0.2,IF(Template!$AB60=4,0.1,IF(Template!$AB60>=5,0.05,"erro"))))) -> 0.05 | AD60: =Template!$D60=Template!$M60 -> FALSE | AE60: ab28b61c-af05-49c5-9d7a-0a76ad62ccfc
A61: MATRIZ | B61: TECNOLOGIA DA INFORMAÇÃO | C61: TECNOLOGIA DA INFORMAÇÃO | D61: 25348 | E61: COORDENADOR DE TI | F61: 18 | G61: Coordenador | H61: SP | I61: SÃO PAULO | J61: Feminino | K61: 45537 | L61: 32928 | M61: 24945 | N61: 12000 | P61: 13.33 | Q61: 18000 | R61: 0 | U61: =SUM(Template!$N61:$O61)*Template!$P61+Template!$Q61 -> 177960 | V61: =IF(Template!$M61="CONSELHO","N",IF(Template!$AA61="N","N1",IF(Template!$AA61="N1","N2",IF(Template!$AA61="N2","N3",IF(Template!$AA61="N3","N4",IF(Template!$AA61="N4","N5",IF(Template!$AA61="N5","N6",IF(Template!$AA61="N6","N7",IF(Template!$AA61="N7","N8",IF(Template!$AA61="N8","N9",IF(Template!$AA61="N9","N10","NA"))))))))))) -> N2 | W61: =COUNTIF(Template!$M$3:$M$619,Template!$D61) -> 5 | X61: =IF(Template!$F61="","",SUMIF(Template!$M$3:$M$619,Template!$D61,Template!$AC$3:$AC$619)) -> 0.7 | Y61: =IFERROR(VLOOKUP(Template!$M61,Template!$D$3:$G$619,MATCH("EmployeeJobTitle",Template!$D$2:$G$2,0),FALSE),"NA") -> GERENTE SISTEMA DA INFORMAÇÃO | Z61: =IFERROR(VLOOKUP(Template!$M61,Template!$D$3:$G$619,MATCH("EmployeeGroup",Template!$D$2:$G$2,0),FALSE),"NA") -> Gerente | AA61: =IFERROR(VLOOKUP(Template!$M61,Template!$D$3:$V$619,MATCH("Layer",Template!$D$2:$V$2,0),FALSE),"NA") -> N1 | AB61: =VLOOKUP(Template!$M61,Template!$D$3:$F$619,MATCH("InternalGrade",Template!$D$2:$F$2,0),FALSE)-Template!$F61 -> 1 | AC61: =IF(Template!$AB61<=1, 0.8,IF(Template!$AB61=2,0.4,IF(Template!$AB61=3,0.2,IF(Template!$AB61=4,0.1,IF(Template!$AB61>=5,0.05,"erro"))))) -> 0.8 | AD61: =Template!$D61=Template!$M61 -> FALSE | AE61: ab28b61c-af05-49c5-9d7a-0a76ad62ccfc
A62: MATRIZ | B62: COMPRAS E LOGÍSTICA | C62: COMPRAS E MANUTENÇÃO | D62: 17952 | E62: COORDENADOR DE PRODUTOS | F62: 19 | G62: Coordenador | H62: SP | I62: SÃO PAULO | J62: Feminino | K62: 43763 | L62: 27445 | M62: 23261 | N62: 17666 | P62: 13.33 | Q62: 26499 | R62: 0 | U62: =SUM(Template!$N62:$O62)*Template!$P62+Template!$Q62 -> 261986.78 | V62: =IF(Template!$M62="CONSELHO","N",IF(Template!$AA62="N","N1",IF(Template!$AA62="N1","N2",IF(Template!$AA62="N2","N3",IF(Template!$AA62="N3","N4",IF(Template!$AA62="N4","N5",IF(Template!$AA62="N5","N6",IF(Template!$AA62="N6","N7",IF(Template!$AA62="N7","N8",IF(Template!$AA62="N8","N9",IF(Template!$AA62="N9","N10","NA"))))))))))) -> N2 | W62: =COUNTIF(Template!$M$3:$M$619,Template!$D62) -> 4 | X62: =IF(Template!$F62="","",SUMIF(Template!$M$3:$M$619,Template!$D62,Template!$AC$3:$AC$619)) -> 0.75 | Y62: =IFERROR(VLOOKUP(Template!$M62,Template!$D$3:$G$619,MATCH("EmployeeJobTitle",Template!$D$2:$G$2,0),FALSE),"NA") -> DIRETORA DE COMPRAS E LOGISTICA | Z62: =IFERROR(VLOOKUP(Template!$M62,Template!$D$3:$G$619,MATCH("EmployeeGroup",Template!$D$2:$G$2,0),FALSE),"NA") -> Diretor | AA62: =IFERROR(VLOOKUP(Template!$M62,Template!$D$3:$V$619,MATCH("Layer",Template!$D$2:$V$2,0),FALSE),"NA") -> N1 | AB62: =VLOOKUP(Template!$M62,Template!$D$3:$F$619,MATCH("InternalGrade",Template!$D$2:$F$2,0),FALSE)-Template!$F62 -> 2 | AC62: =IF(Template!$AB62<=1, 0.8,IF(Template!$AB62=2,0.4,IF(Template!$AB62=3,0.2,IF(Template!$AB62=4,0.1,IF(Template!$AB62>=5,0.05,"erro"))))) -> 0.4 | AD62: =Template!$D62=Template!$M62 -> FALSE | AE62: ab28b61c-af05-49c5-9d7a-0a76ad62ccfc
A63: MATRIZ | B63: FINANÇAS | C63: DIRETORIA ADMINISTRATIVA FINANCEIRA | D63: 24782 | E63: ANALISTA PLANEJAMENTO FINANCEIRO SR | F63: 16 | G63: Operacionais / Profissionais | H63: SP | I63: SÃO PAULO | J63: Feminino | K63: 45293 | L63: 37203 | M63: 24245 | N63: 6720 | P63: 13.33 | Q63: 6720 | R63: 0 | U63: =SUM(Template!$N63:$O63)*Template!$P63+Template!$Q63 -> 96297.6 | V63: =IF(Template!$M63="CONSELHO","N",IF(Template!$AA63="N","N1",IF(Template!$AA63="N1","N2",IF(Template!$AA63="N2","N3",IF(Template!$AA63="N3","N4",IF(Template!$AA63="N4","N5",IF(Template!$AA63="N5","N6",IF(Template!$AA63="N6","N7",IF(Template!$AA63="N7","N8",IF(Template!$AA63="N8","N9",IF(Template!$AA63="N9","N10","NA"))))))))))) -> N3 | W63: =COUNTIF(Template!$M$3:$M$619,Template!$D63) -> 0 | X63: =IF(Template!$F63="","",SUMIF(Template!$M$3:$M$619,Template!$D63,Template!$AC$3:$AC$619)) -> 0 | Y63: =IFERROR(VLOOKUP(Template!$M63,Template!$D$3:$G$619,MATCH("EmployeeJobTitle",Template!$D$2:$G$2,0),FALSE),"NA") -> GERENTE DE PLAN. FINANCEIRO | Z63: =IFERROR(VLOOKUP(Template!$M63,Template!$D$3:$G$619,MATCH("EmployeeGroup",Template!$D$2:$G$2,0),FALSE),"NA") -> Gerente | AA63: =IFERROR(VLOOKUP(Template!$M63,Template!$D$3:$V$619,MATCH("Layer",Template!$D$2:$V$2,0),FALSE),"NA") -> N2 | AB63: =VLOOKUP(Template!$M63,Template!$D$3:$F$619,MATCH("InternalGrade",Template!$D$2:$F$2,0),FALSE)-Template!$F63 -> 3 | AC63: =IF(Template!$AB63<=1, 0.8,IF(Template!$AB63=2,0.4,IF(Template!$AB63=3,0.2,IF(Template!$AB63=4,0.1,IF(Template!$AB63>=5,0.05,"erro"))))) -> 0.2 | AD63: =Template!$D63=Template!$M63 -> FALSE | AE63: ab28b61c-af05-49c5-9d7a-0a76ad62ccfc
A64: MATRIZ | B64: COMERCIAL | C64: E-COMMERCE | D64: 20450 | E64: COORDENADOR DE ECOMMERCE | F64: 18 | G64: Coordenador | H64: SP | I64: SÃO PAULO | J64: Feminino | K64: 44655 | L64: 35347 | M64: 24307 | N64: 10690 | P64: 13.33 | Q64: 16035 | R64: 0 | U64: =SUM(Template!$N64:$O64)*Template!$P64+Template!$Q64 -> 158532.7 | V64: =IF(Template!$M64="CONSELHO","N",IF(Template!$AA64="N","N1",IF(Template!$AA64="N1","N2",IF(Template!$AA64="N2","N3",IF(Template!$AA64="N3","N4",IF(Template!$AA64="N4","N5",IF(Template!$AA64="N5","N6",IF(Template!$AA64="N6","N7",IF(Template!$AA64="N7","N8",IF(Template!$AA64="N8","N9",IF(Template!$AA64="N9","N10","NA"))))))))))) -> N2 | W64: =COUNTIF(Template!$M$3:$M$619,Template!$D64) -> 5 | X64: =IF(Template!$F64="","",SUMIF(Template!$M$3:$M$619,Template!$D64,Template!$AC$3:$AC$619)) -> 0.75 | Y64: =IFERROR(VLOOKUP(Template!$M64,Template!$D$3:$G$619,MATCH("EmployeeJobTitle",Template!$D$2:$G$2,0),FALSE),"NA") -> DIRETOR COMERCIAL | Z64: =IFERROR(VLOOKUP(Template!$M64,Template!$D$3:$G$619,MATCH("EmployeeGroup",Template!$D$2:$G$2,0),FALSE),"NA") -> Diretor | AA64: =IFERROR(VLOOKUP(Template!$M64,Template!$D$3:$V$619,MATCH("Layer",Template!$D$2:$V$2,0),FALSE),"NA") -> N1 | AB64: =VLOOKUP(Template!$M64,Template!$D$3:$F$619,MATCH("InternalGrade",Template!$D$2:$F$2,0),FALSE)-Template!$F64 -> 4 | AC64: =IF(Template!$AB64<=1, 0.8,IF(Template!$AB64=2,0.4,IF(Template!$AB64=3,0.2,IF(Template!$AB64=4,0.1,IF(Template!$AB64>=5,0.05,"erro"))))) -> 0.1 | AD64: =Template!$D64=Template!$M64 -> FALSE | AE64: ab28b61c-af05-49c5-9d7a-0a76ad62ccfc
A65: MATRIZ | B65: PRODUTO E ESTILO | C65: GERENCIA DE ESTILO | D65: 17138 | E65: MODELISTA | F65: 15 | G65: Operacionais / Profissionais | H65: SP | I65: SÃO PAULO | J65: Feminino | K65: 43395 | L65: 25039 | M65: 23265 | N65: 6251 | P65: 13.33 | Q65: 6251 | R65: 0 | U65: =SUM(Template!$N65:$O65)*Template!$P65+Template!$Q65 -> 89576.83 | V65: =IF(Template!$M65="CONSELHO","N",IF(Template!$AA65="N","N1",IF(Template!$AA65="N1","N2",IF(Template!$AA65="N2","N3",IF(Template!$AA65="N3","N4",IF(Template!$AA65="N4","N5",IF(Template!$AA65="N5","N6",IF(Template!$AA65="N6","N7",IF(Template!$AA65="N7","N8",IF(Template!$AA65="N8","N9",IF(Template!$AA65="N9","N10","NA"))))))))))) -> N2 | W65: =COUNTIF(Template!$M$3:$M$619,Template!$D65) -> 0 | X65: =IF(Template!$F65="","",SUMIF(Template!$M$3:$M$619,Template!$D65,Template!$AC$3:$AC$619)) -> 0 | Y65: =IFERROR(VLOOKUP(Template!$M65,Template!$D$3:$G$619,MATCH("EmployeeJobTitle",Template!$D$2:$G$2,0),FALSE),"NA") -> DIRETORA DE PRODUTO E ESTILO | Z65: =IFERROR(VLOOKUP(Template!$M65,Template!$D$3:$G$619,MATCH("EmployeeGroup",Template!$D$2:$G$2,0),FALSE),"NA") -> Diretor | AA65: =IFERROR(VLOOKUP(Template!$M65,Template!$D$3:$V$619,MATCH("Layer",Template!$D$2:$V$2,0),FALSE),"NA") -> N1 | AB65: =VLOOKUP(Template!$M65,Template!$D$3:$F$619,MATCH("InternalGrade",Template!$D$2:$F$2,0),FALSE)-Template!$F65 -> 6 | AC65: =IF(Template!$AB65<=1, 0.8,IF(Template!$AB65=2,0.4,IF(Template!$AB65=3,0.2,IF(Template!$AB65=4,0.1,IF(Template!$AB65>=5,0.05,"erro"))))) -> 0.05 | AD65: =Template!$D65=Template!$M65 -> FALSE | AE65: ab28b61c-af05-49c5-9d7a-0a76ad62ccfc
A66: MATRIZ | B66: COMPRAS E LOGÍSTICA | C66: COMPRAS E MANUTENÇÃO | D66: 23893 | E66: COMPRADOR PL | F66: 16 | G66: Operacionais / Profissionais | H66: SP | I66: SÃO PAULO | J66: Feminino | K66: 44998 | L66: 32095 | M66: 17952 | N66: 6868 | P66: 13.33 | Q66: 6868 | R66: 0 | U66: =SUM(Template!$N66:$O66)*Template!$P66+Template!$Q66 -> 98418.44 | V66: =IF(Template!$M66="CONSELHO","N",IF(Template!$AA66="N","N1",IF(Template!$AA66="N1","N2",IF(Template!$AA66="N2","N3",IF(Template!$AA66="N3","N4",IF(Template!$AA66="N4","N5",IF(Template!$AA66="N5","N6",IF(Template!$AA66="N6","N7",IF(Template!$AA66="N7","N8",IF(Template!$AA66="N8","N9",IF(Template!$AA66="N9","N10","NA"))))))))))) -> N3 | W66: =COUNTIF(Template!$M$3:$M$619,Template!$D66) -> 0 | X66: =IF(Template!$F66="","",SUMIF(Template!$M$3:$M$619,Template!$D66,Template!$AC$3:$AC$619)) -> 0 | Y66: =IFERROR(VLOOKUP(Template!$M66,Template!$D$3:$G$619,MATCH("EmployeeJobTitle",Template!$D$2:$G$2,0),FALSE),"NA") -> COORDENADOR DE PRODUTOS | Z66: =IFERROR(VLOOKUP(Template!$M66,Template!$D$3:$G$619,MATCH("EmployeeGroup",Template!$D$2:$G$2,0),FALSE),"NA") -> Coordenador | AA66: =IFERROR(VLOOKUP(Template!$M66,Template!$D$3:$V$619,MATCH("Layer",Template!$D$2:$V$2,0),FALSE),"NA") -> N2 | AB66: =VLOOKUP(Template!$M66,Template!$D$3:$F$619,MATCH("InternalGrade",Template!$D$2:$F$2,0),FALSE)-Template!$F66 -> 3 | AC66: =IF(Template!$AB66<=1, 0.8,IF(Template!$AB66=2,0.4,IF(Template!$AB66=3,0.2,IF(Template!$AB66=4,0.1,IF(Template!$AB66>=5,0.05,"erro"))))) -> 0.2 | AD66: =Template!$D66=Template!$M66 -> FALSE | AE66: ab28b61c-af05-49c5-9d7a-0a76ad62ccfc
A67: MATRIZ | B67: COMPRAS E LOGÍSTICA | C67: COMPRAS E MANUTENÇÃO | D67: 12629 | E67: COMPRADOR SR | F67: 17 | G67: Operacionais / Profissionais | H67: SP | I67: SÃO PAULO | J67: Feminino | K67: 41428 | L67: 33294 | M67: 17952 | N67: 12015.44 | P67: 13.33 | Q67: 12015.44 | R67: 0 | U67: =SUM(Template!$N67:$O67)*Template!$P67+Template!$Q67 -> 172181.26 | V67: =IF(Template!$M67="CONSELHO","N",IF(Template!$AA67="N","N1",IF(Template!$AA67="N1","N2",IF(Template!$AA67="N2","N3",IF(Template!$AA67="N3","N4",IF(Template!$AA67="N4","N5",IF(Template!$AA67="N5","N6",IF(Template!$AA67="N6","N7",IF(Template!$AA67="N7","N8",IF(Template!$AA67="N8","N9",IF(Template!$AA67="N9","N10","NA"))))))))))) -> N3 | W67: =COUNTIF(Template!$M$3:$M$619,Template!$D67) -> 0 | X67: =IF(Template!$F67="","",SUMIF(Template!$M$3:$M$619,Template!$D67,Template!$AC$3:$AC$619)) -> 0 | Y67: =IFERROR(VLOOKUP(Template!$M67,Template!$D$3:$G$619,MATCH("EmployeeJobTitle",Template!$D$2:$G$2,0),FALSE),"NA") -> COORDENADOR DE PRODUTOS | Z67: =IFERROR(VLOOKUP(Template!$M67,Template!$D$3:$G$619,MATCH("EmployeeGroup",Template!$D$2:$G$2,0),FALSE),"NA") -> Coordenador | AA67: =IFERROR(VLOOKUP(Template!$M67,Template!$D$3:$V$619,MATCH("Layer",Template!$D$2:$V$2,0),FALSE),"NA") -> N2 | AB67: =VLOOKUP(Template!$M67,Template!$D$3:$F$619,MATCH("InternalGrade",Template!$D$2:$F$2,0),FALSE)-Template!$F67 -> 2 | AC67: =IF(Template!$AB67<=1, 0.8,IF(Template!$AB67=2,0.4,IF(Template!$AB67=3,0.2,IF(Template!$AB67=4,0.1,IF(Template!$AB67>=5,0.05,"erro"))))) -> 0.4 | AD67: =Template!$D67=Template!$M67 -> FALSE | AE67: ab28b61c-af05-49c5-9d7a-0a76ad62ccfc
A68: MATRIZ | B68: FINANÇAS | C68: CONTROLADORIA | D68: 12070 | E68: ANALISTA CONTÁBIL PL | F68: 15 | G68: Operacionais / Profissionais | H68: SP | I68: SÃO PAULO | J68: Masculino | K68: 41199 | L68: 30221 | M68: 19643 | N68: 5775 | P68: 13.33 | Q68: 5775 | R68: 0 | U68: =SUM(Template!$N68:$O68)*Template!$P68+Template!$Q68 -> 82755.75 | V68: =IF(Template!$M68="CONSELHO","N",IF(Template!$AA68="N","N1",IF(Template!$AA68="N1","N2",IF(Template!$AA68="N2","N3",IF(Template!$AA68="N3","N4",IF(Template!$AA68="N4","N5",IF(Template!$AA68="N5","N6",IF(Template!$AA68="N6","N7",IF(Template!$AA68="N7","N8",IF(Template!$AA68="N8","N9",IF(Template!$AA68="N9","N10","NA"))))))))))) -> N4 | W68: =COUNTIF(Template!$M$3:$M$619,Template!$D68) -> 0 | X68: =IF(Template!$F68="","",SUMIF(Template!$M$3:$M$619,Template!$D68,Template!$AC$3:$AC$619)) -> 0 | Y68: =IFERROR(VLOOKUP(Template!$M68,Template!$D$3:$G$619,MATCH("EmployeeJobTitle",Template!$D$2:$G$2,0),FALSE),"NA") -> COORDENADOR CONTABIL | Z68: =IFERROR(VLOOKUP(Template!$M68,Template!$D$3:$G$619,MATCH("EmployeeGroup",Template!$D$2:$G$2,0),FALSE),"NA") -> Coordenador | AA68: =IFERROR(VLOOKUP(Template!$M68,Template!$D$3:$V$619,MATCH("Layer",Template!$D$2:$V$2,0),FALSE),"NA") -> N3 | AB68: =VLOOKUP(Template!$M68,Template!$D$3:$F$619,MATCH("InternalGrade",Template!$D$2:$F$2,0),FALSE)-Template!$F68 -> 2 | AC68: =IF(Template!$AB68<=1, 0.8,IF(Template!$AB68=2,0.4,IF(Template!$AB68=3,0.2,IF(Template!$AB68=4,0.1,IF(Template!$AB68>=5,0.05,"erro"))))) -> 0.4 | AD68: =Template!$D68=Template!$M68 -> FALSE | AE68: ab28b61c-af05-49c5-9d7a-0a76ad62ccfc
A69: MATRIZ | B69: FINANÇAS | C69: CONTROLADORIA | D69: 25257 | E69: ASSISTENTE FISCAL | F69: 13 | G69: Operacionais / Profissionais | H69: SP | I69: SÃO PAULO | J69: Feminino | K69: 45509 | L69: 35805 | M69: 11398 | N69: 2800 | P69: 13.33 | Q69: 2800 | R69: 0 | U69: =SUM(Template!$N69:$O69)*Template!$P69+Template!$Q69 -> 40124 | V69: =IF(Template!$M69="CONSELHO","N",IF(Template!$AA69="N","N1",IF(Template!$AA69="N1","N2",IF(Template!$AA69="N2","N3",IF(Template!$AA69="N3","N4",IF(Template!$AA69="N4","N5",IF(Template!$AA69="N5","N6",IF(Template!$AA69="N6","N7",IF(Template!$AA69="N7","N8",IF(Template!$AA69="N8","N9",IF(Template!$AA69="N9","N10","NA"))))))))))) -> N4 | W69: =COUNTIF(Template!$M$3:$M$619,Template!$D69) -> 0 | X69: =IF(Template!$F69="","",SUMIF(Template!$M$3:$M$619,Template!$D69,Template!$AC$3:$AC$619)) -> 0 | Y69: =IFERROR(VLOOKUP(Template!$M69,Template!$D$3:$G$619,MATCH("EmployeeJobTitle",Template!$D$2:$G$2,0),FALSE),"NA") -> COORDENADOR FISCAL | Z69: =IFERROR(VLOOKUP(Template!$M69,Template!$D$3:$G$619,MATCH("EmployeeGroup",Template!$D$2:$G$2,0),FALSE),"NA") -> Coordenador | AA69: =IFERROR(VLOOKUP(Template!$M69,Template!$D$3:$V$619,MATCH("Layer",Template!$D$2:$V$2,0),FALSE),"NA") -> N3 | AB69: =VLOOKUP(Template!$M69,Template!$D$3:$F$619,MATCH("InternalGrade",Template!$D$2:$F$2,0),FALSE)-Template!$F69 -> 5 | AC69: =IF(Template!$AB69<=1, 0.8,IF(Template!$AB69=2,0.4,IF(Template!$AB69=3,0.2,IF(Template!$AB69=4,0.1,IF(Template!$AB69>=5,0.05,"erro"))))) -> 0.05 | AD69: =Template!$D69=Template!$M69 -> FALSE | AE69: ab28b61c-af05-49c5-9d7a-0a76ad62ccfc
A70: MATRIZ | B70: COMERCIAL | C70: E-COMMERCE | D70: 25256 | E70: ANALISTA DE ECOMMERCE PL | F70: 15 | G70: Operacionais / Profissionais | H70: SP | I70: SÃO PAULO | J70: Feminino | K70: 45509 | L70: 35739 | M70: 20450 | N70: 4749 | P70: 13.33 | Q70: 4749 | R70: 0 | U70: =SUM(Template!$N70:$O70)*Template!$P70+Template!$Q70 -> 68053.17 | V70: =IF(Template!$M70="CONSELHO","N",IF(Template!$AA70="N","N1",IF(Template!$AA70="N1","N2",IF(Template!$AA70="N2","N3",IF(Template!$AA70="N3","N4",IF(Template!$AA70="N4","N5",IF(Template!$AA70="N5","N6",IF(Template!$AA70="N6","N7",IF(Template!$AA70="N7","N8",IF(Template!$AA70="N8","N9",IF(Template!$AA70="N9","N10","NA"))))))))))) -> N3 | W70: =COUNTIF(Template!$M$3:$M$619,Template!$D70) -> 0 | X70: =IF(Template!$F70="","",SUMIF(Template!$M$3:$M$619,Template!$D70,Template!$AC$3:$AC$619)) -> 0 | Y70: =IFERROR(VLOOKUP(Template!$M70,Template!$D$3:$G$619,MATCH("EmployeeJobTitle",Template!$D$2:$G$2,0),FALSE),"NA") -> COORDENADOR DE ECOMMERCE | Z70: =IFERROR(VLOOKUP(Template!$M70,Template!$D$3:$G$619,MATCH("EmployeeGroup",Template!$D$2:$G$2,0),FALSE),"NA") -> Coordenador | AA70: =IFERROR(VLOOKUP(Template!$M70,Template!$D$3:$V$619,MATCH("Layer",Template!$D$2:$V$2,0),FALSE),"NA") -> N2 | AB70: =VLOOKUP(Template!$M70,Template!$D$3:$F$619,MATCH("InternalGrade",Template!$D$2:$F$2,0),FALSE)-Template!$F70 -> 3 | AC70: =IF(Template!$AB70<=1, 0.8,IF(Template!$AB70=2,0.4,IF(Template!$AB70=3,0.2,IF(Template!$AB70=4,0.1,IF(Template!$AB70>=5,0.05,"erro"))))) -> 0.2 | AD70: =Template!$D70=Template!$M70 -> FALSE | AE70: ab28b61c-af05-49c5-9d7a-0a76ad62ccfc
A71: MATRIZ | B71: COMERCIAL | C71: GERENCIA DE OPERAÇÕES | D71: 25075 | E71: ANALISTA DE INTELIGENCIA COMERCIAL PL | F71: 15 | G71: Operacionais / Profissionais | H71: SP | I71: SÃO PAULO | J71: Feminino | K71: 45432 | L71: 36734 | M71: 21878 | N71: 5000 | P71: 13.33 | Q71: 5000 | R71: 0 | U71: =SUM(Template!$N71:$O71)*Template!$P71+Template!$Q71 -> 71650 | V71: =IF(Template!$M71="CONSELHO","N",IF(Template!$AA71="N","N1",IF(Template!$AA71="N1","N2",IF(Template!$AA71="N2","N3",IF(Template!$AA71="N3","N4",IF(Template!$AA71="N4","N5",IF(Template!$AA71="N5","N6",IF(Template!$AA71="N6","N7",IF(Template!$AA71="N7","N8",IF(Template!$AA71="N8","N9",IF(Template!$AA71="N9","N10","NA"))))))))))) -> N4 | W71: =COUNTIF(Template!$M$3:$M$619,Template!$D71) -> 0 | X71: =IF(Template!$F71="","",SUMIF(Template!$M$3:$M$619,Template!$D71,Template!$AC$3:$AC$619)) -> 0 | Y71: =IFERROR(VLOOKUP(Template!$M71,Template!$D$3:$G$619,MATCH("EmployeeJobTitle",Template!$D$2:$G$2,0),FALSE),"NA") -> COORDENADOR DE INTELIGÊNCIA COMERCIAL | Z71: =IFERROR(VLOOKUP(Template!$M71,Template!$D$3:$G$619,MATCH("EmployeeGroup",Template!$D$2:$G$2,0),FALSE),"NA") -> Coordenador | AA71: =IFERROR(VLOOKUP(Template!$M71,Template!$D$3:$V$619,MATCH("Layer",Template!$D$2:$V$2,0),FALSE),"NA") -> N3 | AB71: =VLOOKUP(Template!$M71,Template!$D$3:$F$619,MATCH("InternalGrade",Template!$D$2:$F$2,0),FALSE)-Template!$F71 -> 3 | AC71: =IF(Template!$AB71<=1, 0.8,IF(Template!$AB71=2,0.4,IF(Template!$AB71=3,0.2,IF(Template!$AB71=4,0.1,IF(Template!$AB71>=5,0.05,"erro"))))) -> 0.2 | AD71: =Template!$D71=Template!$M71 -> FALSE | AE71: ab28b61c-af05-49c5-9d7a-0a76ad62ccfc
A72: MATRIZ | B72: MARKETING | C72: GERENCIA DE VISUAL MERCHADISING | D72: 14939 | E72: ANALISTA DE VM PLENO | F72: 14 | G72: Operacionais / Profissionais | H72: SP | I72: SÃO PAULO | J72: Feminino | K72: 42450 | L72: 34596 | M72: 23266 | N72: 4852 | P72: 13.33 | Q72: 4852 | R72: 0 | U72: =SUM(Template!$N72:$O72)*Template!$P72+Template!$Q72 -> 69529.16 | V72: =IF(Template!$M72="CONSELHO","N",IF(Template!$AA72="N","N1",IF(Template!$AA72="N1","N2",IF(Template!$AA72="N2","N3",IF(Template!$AA72="N3","N4",IF(Template!$AA72="N4","N5",IF(Template!$AA72="N5","N6",IF(Template!$AA72="N6","N7",IF(Template!$AA72="N7","N8",IF(Template!$AA72="N8","N9",IF(Template!$AA72="N9","N10","NA"))))))))))) -> N3 | W72: =COUNTIF(Template!$M$3:$M$619,Template!$D72) -> 0 | X72: =IF(Template!$F72="","",SUMIF(Template!$M$3:$M$619,Template!$D72,Template!$AC$3:$AC$619)) -> 0 | Y72: =IFERROR(VLOOKUP(Template!$M72,Template!$D$3:$G$619,MATCH("EmployeeJobTitle",Template!$D$2:$G$2,0),FALSE),"NA") -> GERENTE DE VM | Z72: =IFERROR(VLOOKUP(Template!$M72,Template!$D$3:$G$619,MATCH("EmployeeGroup",Template!$D$2:$G$2,0),FALSE),"NA") -> Gerente | AA72: =IFERROR(VLOOKUP(Template!$M72,Template!$D$3:$V$619,MATCH("Layer",Template!$D$2:$V$2,0),FALSE),"NA") -> N2 | AB72: =VLOOKUP(Template!$M72,Template!$D$3:$F$619,MATCH("InternalGrade",Template!$D$2:$F$2,0),FALSE)-Template!$F72 -> 5 | AC72: =IF(Template!$AB72<=1, 0.8,IF(Template!$AB72=2,0.4,IF(Template!$AB72=3,0.2,IF(Template!$AB72=4,0.1,IF(Template!$AB72>=5,0.05,"erro"))))) -> 0.05 | AD72: =Template!$D72=Template!$M72 -> FALSE | AE72: ab28b61c-af05-49c5-9d7a-0a76ad62ccfc
